Workbook

Sheet Organisation
A1: Organisation av HSN före och från och med 2015
A4: 1999 - 2014 | D4: 2015 -
A5: HSNkod | B5: HSNnamn | C5: Kommun / stadsdel | D5: HSNnamn | E5: key | F5: value | G5: HSNkod
A6: 1 | B6: N Bohuslän | C6: Lysekil | D6: Norra | E6: 1484 | F6: Norra | G6: ?
C7: Munkedal | E7: 1430 | F7: Norra
C8: Orust | E8: 1421 | F8: Norra
C9: Sotenäs | E9: 1427 | F9: Norra
C10: Strömstad | E10: 1486 | F10: Norra
C11: Tanum | E11: 1435 | F11: Norra
A12: 2 | B12: Dalsland | C12: Bengtsfors | E12: 1460 | F12: Norra
C13: Dals-Ed | E13: 1438 | F13: Norra
C14: Färgelanda | E14: 1439 | F14: Norra
C15: Mellerud | E15: 1461 | F15: Norra
C16: Åmål | E16: 1492 | F16: Norra
A17: 3 | B17: Trestad | C17: Trollhättan | E17: 1488 | F17: Norra
C18: Uddevalla | E18: 1485 | F18: Norra
C19: Vänersborg | E19: 1487 | F19: Norra
C20: Lilla Edet | D20: Västra | E20: 1462 | F20: Västra | G20: ?
A21: 4 | B21: M Bohuslän | C21: Ale | E21: 1440 | F21: Västra
C22: Kungälv | E22: 1482 | F22: Västra
C23: Stenungsund | E23: 1415 | F23: Västra
C24: Tjörn | E24: 1419 | F24: Västra
C25: Öckerö | E25: 1407 | F25: Västra
A26: 7 | B26: S Bohuslän | C26: Härryda | E26: 1401 | F26: Västra
C27: Mölndal | E27: 1481 | F27: Västra
C28: Partille | E28: 1402 | F28: Västra
A29: 6 | B29: Mittenälvsborg | C29: Lerum | E29: 1441 | F29: Västra
C30: Alingsås | E30: 1489 | F30: Västra
C31: Herrljunga | D31: Södra | E31: 1466 | F31: Södra | G31: ?
C32: Vårgårda | E32: 1442 | F32: Södra
A33: 8 | B33: Sjuhärad | C33: Bollebygd | E33: 1443 | F33: Södra
C34: Borås | E34: 1490 | F34: Södra
C35: Mark | E35: 1463 | F35: Södra
C36: Svenljunga | E36: 1465 | F36: Södra
C37: Tranemo | E37: 1452 | F37: Södra
C38: Ulricehamn | E38: 1491 | F38: Södra
A39: 5 | B39: Göteborg, Centrum-Väster | C39: Askim-Frölunda-Högsbo | D39: Göteborg | E39: 1480 | F39: Göteborg | G39: ?
C40: Centrum | E40: 1480 | F40: Göteborg
C41: Majorna-Linné | E41: 1480 | F41: Göteborg
C42: Västra Göteborg | E42: 1480 | F42: Göteborg
...

Sheet Antal invånare
A1: Organisation av HSN före och från och med 2015
A4: 1999 - 2014 | F4: 2015 -
A5: HSNkod | B5: HSNnamn | C5: Antal invån | D5: Kommun / stadsdel | E5: Antal invån | F5: HSNnamn | G5: Antal invån | H5: HSNkod
A6: 1 | B6: N Bohuslän | C6: =SUM(E6:E11) -> 73321 | D6: Lysekil | E6: =SUM(Blad1!F7) -> 14369 | F6: Norra | G6: =SUM(E6:E19) -> 237679 | H6: ?
D7: Munkedal | E7: =SUM(Blad1!F8) -> 10205
D8: Orust | E8: =SUM(Blad1!F9) -> 15036
D9: Sotenäs | E9: =SUM(Blad1!F10) -> 8928
D10: Strömstad | E10: =SUM(Blad1!F11) -> 12480
D11: Tanum | E11: =SUM(Blad1!F12) -> 12303
A12: 2 | B12: Dalsland | C12: =SUM(E12:E16) -> 41931 | D12: Bengtsfors | E12: =SUM(Blad1!F13) -> 9550
D13: Dals-Ed | E13: =SUM(Blad1!F14) -> 4740
D14: Färgelanda | E14: =SUM(Blad1!F15) -> 6520
D15: Mellerud | E15: =SUM(Blad1!F16) -> 8892
D16: Åmål | E16: =SUM(Blad1!F17) -> 12229
A17: 3 | B17: Trestad | C17: =SUM(E17:E20) -> 159796 | D17: Trollhättan | E17: =SUM(Blad1!F18) -> 12829
D18: Uddevalla | E18: =SUM(Blad1!F19) -> 56573
D19: Vänersborg | E19: =SUM(Blad1!F20) -> 53025
D20: Lilla Edet | E20: =SUM(Blad1!F21) -> 37369 | F20: Västra | G20: =SUM(E20:E30) -> 371903 | H20: ?
A21: 4 | B21: M Bohuslän | C21: =SUM(E21:E25) -> 122739 | D21: Ale | E21: =SUM(Blad1!F22) -> 28074
D22: Kungälv | E22: =SUM(Blad1!F23) -> 42109
D23: Stenungsund | E23: =SUM(Blad1!F24) -> 24932
D24: Tjörn | E24: =SUM(Blad1!F25) -> 15050
D25: Öckerö | E25: =SUM(Blad1!F26) -> 12574
A26: 7 | B26: S Bohuslän | C26: =SUM(E26:E28) -> 133857 | D26: Härryda | E26: =SUM(Blad1!F35) -> 35732
D27: Mölndal | E27: =SUM(Blad1!F36) -> 61978
D28: Partille | E28: =SUM(Blad1!F37) -> 36147
A29: 6 | B29: Mittenälvsborg | C29: =SUM(E29:E32) -> 98277 | D29: Lerum | E29: =SUM(Blad1!F33) -> 39319
D30: Alingsås | E30: =SUM(Blad1!F31) -> 38619
D31: Herrljunga | E31: =SUM(Blad1!F32) -> 9274 | F31: Södra | G31: =SUM(E31:E38) -> 213690 | H31: ?
D32: Vårgårda | E32: =SUM(Blad1!F34) -> 11065
A33: 8 | B33: Sjuhärad | C33: =SUM(E33:E38) -> 193351 | D33: Bollebygd | E33: =SUM(Blad1!F38) -> 8562
D34: Borås | E34: =SUM(Blad1!F39) -> 105995
D35: Mark | E35: =SUM(Blad1!F40) -> 33753
D36: Svenljunga | E36: =SUM(Blad1!F41) -> 10299
D37: Tranemo | E37: =SUM(Blad1!F42) -> 11531
D38: Ulricehamn | E38: =SUM(Blad1!F43) -> 23211
A39: 5 | B39: Göteborg, Centrum-Väster | C39: =SUM(E39+E40+E41+E42+Blad1!J28) -> 231508.29 | D39: Askim-Frölunda-Högsbo | E39: =SUM(Blad1!F27) -> 56498 | F39: Göteborg | G39: =SUM(E39+E40+E41+E42+E43+E44+E45+E46+E47+E48+Blad1!J66) -> 533271 | H39: ?
D40: Centrum | E40: =SUM(Blad1!F28) -> 59071
D41: Majorna-Linné | E41: =SUM(Blad1!F29) -> 63126
D42: Västra Göteborg | E42: =SUM(Blad1!F30) -> 52110
...

Sheet Blad1
A1: Folkmängd 2013
B6: HSNKOD | C6: Kommun eller stadsdel | D6: Kvinnor | E6: Män | F6: Totalt*
B7: 1 | C7: Lysekil | D7: 7224 | E7: 7145 | F7: =D7+E7 -> 14369
C8: Munkedal | D8: 4952 | E8: 5253 | F8: =D8+E8 -> 10205
C9: Orust | D9: 7428 | E9: 7608 | F9: =D9+E9 -> 15036 | K9: =SUM(F7:F12) -> 73321
C10: Sotenäs | D10: 4430 | E10: 4498 | F10: =D10+E10 -> 8928
C11: Strömstad | D11: 6214 | E11: 6266 | F11: =D11+E11 -> 12480
C12: Tanum | D12: 6098 | E12: 6205 | F12: =D12+E12 -> 12303
B13: 2 | C13: Bengtsfors | D13: 4637 | E13: 4913 | F13: =D13+E13 -> 9550
C14: Dals-Ed | D14: 2283 | E14: 2457 | F14: =D14+E14 -> 4740
C15: Färgelanda | D15: 3137 | E15: 3383 | F15: =D15+E15 -> 6520 | K15: =SUM(F13:F17) -> 41931
C16: Mellerud | D16: 4322 | E16: 4570 | F16: =D16+E16 -> 8892
C17: Åmål | D17: 6150 | E17: 6079 | F17: =D17+E17 -> 12229
B18: 3 | C18: Lilla Edet | D18: 6184 | E18: 6645 | F18: =D18+E18 -> 12829
C19: Trollhättan | D19: 28216 | E19: 28357 | F19: =D19+E19 -> 56573 | K19: =SUM(F18:F21) -> 159796
C20: Uddevalla | D20: 26783 | E20: 26242 | F20: =D20+E20 -> 53025
C21: Vänersborg | D21: 18703 | E21: 18666 | F21: =D21+E21 -> 37369
B22: 4 | C22: Ale | D22: 13794 | E22: 14280 | F22: =D22+E22 -> 28074
C23: Kungälv | D23: 21130 | E23: 20979 | F23: =D23+E23 -> 42109
C24: Stenungsund | D24: 12437 | E24: 12495 | F24: =D24+E24 -> 24932 | K24: =SUM(F22:F26) -> 122739
C25: Tjörn | D25: 7344 | E25: 7706 | F25: =D25+E25 -> 15050
C26: Öckerö | D26: 6267 | E26: 6307 | F26: =D26+E26 -> 12574
B27: 5 | C27: Askim-Frölunda-Högsbo | D27: 29267 | E27: 27231 | F27: =D27+E27 -> 56498
C28: Centrum | D28: 29567 | E28: 29504 | F28: =D28+E28 -> 59071 | H28: =SUM(F27:F30) -> 230805 | I28: =SUM(H28/H66) -> 0.43412878 | J28: =SUM(I28*F65) -> 703.28862 | K28: =SUM(H28+J28) -> 231508.29
C29: Majorna-Linné | D29: 32819 | E29: 30307 | F29: =D29+E29 -> 63126
C30: Västra Göteborg | D30: 26294 | E30: 25816 | F30: =D30+E30 -> 52110
B31: 6 | C31: Alingsås | D31: 19503 | E31: 19116 | F31: =D31+E31 -> 38619
C32: Herrljunga | D32: 4560 | E32: 4714 | F32: =D32+E32 -> 9274 | K32: =SUM(F31:F34) -> 98277
C33: Lerum | D33: 19689 | E33: 19630 | F33: =D33+E33 -> 39319
C34: Vårgårda | D34: 5494 | E34: 5571 | F34: =D34+E34 -> 11065
B35: 7 | C35: Härryda | D35: 17779 | E35: 17953 | F35: =D35+E35 -> 35732
C36: Mölndal | D36: 31129 | E36: 30849 | F36: =D36+E36 -> 61978 | K36: =SUM(F35:F37) -> 133857
C37: Partille | D37: 18145 | E37: 18002 | F37: =D37+E37 -> 36147
B38: 8 | C38: Bollebygd | D38: 4239 | E38: 4323 | F38: =D38+E38 -> 8562
C39: Borås | D39: 53641 | E39: 52354 | F39: =D39+E39 -> 105995
C40: Mark | D40: 16844 | E40: 16909 | F40: =D40+E40 -> 33753 | K40: =SUM(F38:F43) -> 193351
C41: Svenljunga | D41: 5041 | E41: 5258 | F41: =D41+E41 -> 10299
C42: Tranemo | D42: 5615 | E42: 5916 | F42: =D42+E42 -> 11531
C43: Ulricehamn | D43: 11501 | E43: 11710 | F43: =D43+E43 -> 23211
B44: 9 | C44: Essunga | D44: 2730 | E44: 2764 | F44: =D44+E44 -> 5494
...
